Workbook
Name BusinessDomains: Config!$D$48:$D$53
Name CurrentStates: Config!$F$48:$F$52
Name EnablerIDs: Enablers!$B$8:$B$15
Name ImpactFactorIDs: Config!$C$22:$C$27
Name ImpactFactors: Config!$C$22:$E$28
Name InvestmentThemes: Config!$C$48:$C$58
Name ReadinessFactorIDs: Config!$C$35:$C$41
Name ReadinessFactors: Config!$C$35:$E$41
Name RegulatoryRisk: Config!$E$48:$E$50
Name UseCaseIDs: 'Use Cases'!$B$7:$B$106

Sheet README
B2: AI OPPORTUNITY MAP — DATA WORKBOOK
B3: Sample Retail Insurance Firm | v1.0 | Import/export format for the AI Opportunity Map visualisation tool
B5: ABOUT THIS WORKBOOK
B6: This workbook is the source of truth for all use case scoring, factor definitions and implementation enabler data. The HTML visualisation tool reads this workbook on import and writes session changes back to it on export. The Config tab is the authoritative source for schema structure — the number and identity of impact factors, readiness factors and enablers is determined by reading the Config tables, not by hardcoded column counts.
B8: TAB STRUCTURE
B9: README | D9: This sheet. Overview, setup guidance and conventions.
B10: Config | D10: Engagement metadata, factor definitions, enabler count, and dropdown lookup tables. Edit this first for a new engagement. The Metadata section provides counts used by the import parser.
B11: Enablers | D11: One row per implementation enabler. Fixed fields first, then one dynamic column per readiness factor (max uplift values). Column headers in row 7 are the RF IDs (machine-readable); row 8 shows friendly names via VLOOKUP.
B12: Use Cases | D12: One row per use case. Fixed descriptive fields, Notes column, then pipe-delimited relationship fields. Dropdowns reference lookup tables in Config.
B13: Impact Scores | D13: One row per use case. Fixed columns (ID, Name), then one dynamic column per impact factor. Column headers in row 6 are IF IDs; row 7 shows friendly names. Weighted score is calculated automatically.
B14: Readiness Scores | D14: One row per use case. Same structure as Impact Scores but for readiness factors.
B16: SETUP SEQUENCE FOR A NEW ENGAGEMENT
B17: 1. Config — update engagement name/date. Add, remove or rename impact and readiness factors. Adjust default weights. Update dropdown lookup tables if needed.
B18: 2. Enablers — replace or update enabler rows to match the engagement. Set initial completion levels. Add/remove RF uplift columns to match the readiness factors defined in Config.
B19: 3. Use Cases — add or replace use case rows. Use pipe | to separate multiple values in Enables and Implementation Enablers columns.
B20: 4. Impact Scores — add a row for each use case (ID in col B, name auto-populates). Add columns for any new impact factors, using the IF ID as the column header in row 6.
B21: 5. Readiness Scores — same pattern for readiness factors.
B22: 6. Load the workbook into the HTML tool using the Import function.
B24: KEY CONVENTIONS
B25: • Multi-value fields (Enables, Implementation Enablers) use pipe | as delimiter: e.g. EN01|EN03|EN07
B26: • Completion levels are integers: 0=Not started, 1=Initial, 2=Partial, 3=Substantial, 4=Comprehensive
B27: • Max uplift values are integers 1–4. Leave blank if an enabler does not affect a given readiness factor.
B28: • Factor ID columns (IF01, RF01 etc.) in score tab row 6/7 are machine-readable — do not rename or reorder them.
... B31: • The Metadata section in Config is used by the import parser. Values update automatically as rows are added.

Sheet Config
B2: ENGAGEMENT CONFIGURATION
C4: Engagement name | D4: Sample Retail Insurance Firm
C5: Version | D5: 1.0
C6: Date
C7: Prepared by
B10: SCHEMA METADATA — used by import/export parser
B11: These counts are derived automatically from the factor tables below. The import parser reads these cells to determine how many columns to expect in the score tabs. Do not edit manually.
C12: Item | D12: Count | E12: Note
C13: Impact factors | D13: =COUNTIF(C22:C47,"IF*") -> 7 | E13: Count of defined impact factors (auto)
C14: Readiness factors | D14: =COUNTIF(C35:C66,"RF*") -> 7 | E14: Count of defined readiness factors (auto)
C15: Implementation enablers | D15: =COUNTIF(Enablers!B7:B106,"EN*") -> 9 | E15: Count of enablers (auto from Enablers tab)
C16: Use cases | D16: =COUNTIF('Use Cases'!B7:B506,"UC*") -> 31 | E16: Count of use cases (auto from Use Cases tab)
B19: IMPACT FACTORS
B20: Define the dimensions used to score business impact. Add or remove rows as needed — the Metadata section updates automatically. Default Weight is the starting weight in the visualisation tool; weights are relative (need not sum to 100).
C21: Factor ID | D21: Factor Name | E21: Default Weight | F21: Description
C22: IF01 | D22: Revenue growth | E22: 20 | F22: Direct contribution to top-line revenue — new income streams, higher conversion, increased wallet share.
C23: IF02 | D23: Cost reduction / efficiency | E23: 20 | F23: Reduction in operating cost, headcount requirement, processing time or error rates.
C24: IF03 | D24: Risk reduction | E24: 20 | F24: Reduction in regulatory, operational, underwriting, claims or reputational risk exposure.
C25: IF04 | D25: Customer experience | E25: 15 | F25: Improvement in client satisfaction, retention, NPS or perceived service quality.
C26: IF05 | D26: Strategic differentiation | E26: 15 | F26: Contribution to competitive positioning, brand or capability that is hard to replicate.
C27: IF06 | D27: Employee experience | E27: 10 | F27: Improvement in staff productivity, satisfaction, or reduction in low-value workload.
C28: IF07 | D28: Learning | E28: 20 | F28: Supports internal learning and skills outcomes (for example, helping people become more AI-literate)
C29: TOTAL | E29: =SUM(E22:E28) -> 120 | F29: ← Relative weights; normalised on import (does not need to add to 100)
B32: READINESS FACTORS
B33: Define the dimensions used to score technical readiness. Add or remove rows as needed. Base scores are entered in the Readiness Scores tab; enabler uplift is modelled in the Enablers tab.
C34: Factor ID | D34: Factor Name | E34: Default Weight | F34: Description
C35: RF01 | D35: Data availability & quality | E35: 20 | F35: Data exists, is accessible, sufficiently clean and usable within consent constraints.
C36: RF02 | D36: Technical infrastructure | E36: 15 | F36: Cloud, compute, storage, API connectivity and integration architecture.
C37: RF03 | D37: Governance & compliance readiness | E37: 20 | F37: AI policies, model risk framework, regulatory approvals and audit trails.
C38: RF04 | D38: Organisational & process readiness | E38: 15 | F38: Business processes, roles, handoff points and change management capability.
C39: RF05 | D39: Skills & capability | E39: 10 | F39: Technical, domain and AI literacy skills available or accessible.
C40: RF06 | D40: Implementation effort | E40: 10 | F40: Inverse of complexity — high score means lower effort. Acts as friction factor.
C41: RF07 | D41: Executive & stakeholder support | E41: 10 | F41: Sponsorship, budget commitment and stakeholder alignment.
C42: TOTAL | E42: =SUM(E35:E41) -> 100 | F42: ← Relative weights; normalised on import (does not need to add to 100)
B45: DROPDOWN LOOKUP TABLES
B46: These tables drive the dropdown lists in the Use Cases tab. Edit the values here to change available options. Do not leave blank rows within a list. If you add values, you will need to update the named ranges that refer to these lists to enable lookup elsewhere.
C47: Investment Themes | D47: Business Domains | E47: Regulatory Risk | F47: Current States
C48: Efficiency | D48: Claims | E48: Low | F48: Hypothetical
C49: Intelligence | D49: Personal Lines Underwriting | E49: Medium | F49: Identified
C50: Engagement | D50: Customer & Distribution | E50: High | F50: Piloted
...

Sheet Enablers
B2: IMPLEMENTATION ENABLERS
B3: These values enable readiness levels to be adjusted based on assumptions about foundational investments, to help with future planning. Each enabler can have an impact on any of the readiness factors, according to relevance, based on moving from its current level ("Completion Level") to maximum completion (Level 4, "Comprehensive") One row per enabler. Completion level: 0=Not started … 4=Comprehensive. Max uplift columns (right section): integer 1–4, blank if no effect. The import parser identifies RF columns by their ID headers in row 7.
B5: FIXED FIELDS | I5: MAX UPLIFT PER READINESS FACTOR (at Comprehensive completion)
I6: {=IFERROR(INDEX(ReadinessFactors, COLUMN()-8, 1), "")} -> RF01 | J6: {=IFERROR(INDEX(ReadinessFactors, COLUMN()-8, 1), "")} -> RF02 | K6: {=IFERROR(INDEX(ReadinessFactors, COLUMN()-8, 1), "")} -> RF03 | L6: {=IFERROR(INDEX(ReadinessFactors, COLUMN()-8, 1), "")} -> RF04 | M6: {=IFERROR(INDEX(ReadinessFactors, COLUMN()-8, 1), "")} -> RF05 | N6: {=IFERROR(INDEX(ReadinessFactors, COLUMN()-8, 1), "")} -> RF06 | O6: {=IFERROR(INDEX(ReadinessFactors, COLUMN()-8, 1), "")} -> RF07 | P6: {=IFERROR(INDEX(ReadinessFactors, COLUMN()-8, 1), "")} | ... R6: {=IFERROR(INDEX(ReadinessFactors, COLUMN()-8, 1), "")}
B7: Enabler ID | C7: Name | D7: Category | E7: Effort | F7: Completion Level | G7: Completion Label | H7: Notes (not exported) | I7: =IFERROR(VLOOKUP(I6,ReadinessFactors,2,FALSE()),I6) -> Data availability & quality | J7: =IFERROR(VLOOKUP(J6,ReadinessFactors,2,FALSE()),J6) -> Technical infrastructure | K7: =IFERROR(VLOOKUP(K6,ReadinessFactors,2,FALSE()),K6) -> Governance & compliance readiness | L7: =IFERROR(VLOOKUP(L6,ReadinessFactors,2,FALSE()),L6) -> Organisational & process readiness | M7: =IFERROR(VLOOKUP(M6,ReadinessFactors,2,FALSE()),M6) -> Skills & capability | N7: =IFERROR(VLOOKUP(N6,ReadinessFactors,2,FALSE()),N6) -> Implementation effort | O7: =IFERROR(VLOOKUP(O6,ReadinessFactors,2,FALSE()),O6) -> Executive & stakeholder support | P7: =IFERROR(VLOOKUP(P6,ReadinessFactors,2,FALSE()),P6) | ... R7: =IFERROR(VLOOKUP(R6,ReadinessFactors,2,FALSE()),R6)
B8: EN01 | C8: Unified data platform & MLOps | D8: Data & Infrastructure | E8: XL | F8: 1 | G8: =IF(F8=0,"Not started",IF(F8=1,"Initial",IF(F8=2,"Partial",IF(F8=3,"Substantial","Comprehensive")))) -> Initial | I8: 2 | J8: 2 | N8: 1
B9: EN02 | C9: Data governance & metadata management | D9: Data & Infrastructure | E9: L | F9: 2 | G9: =IF(F9=0,"Not started",IF(F9=1,"Initial",IF(F9=2,"Partial",IF(F9=3,"Substantial","Comprehensive")))) -> Partial | I9: 2 | K9: 1 | L9: 1
B10: EN03 | C10: AI governance framework & model risk policy | D10: Governance & Compliance | E10: M | F10: 2 | G10: =IF(F10=0,"Not started",IF(F10=1,"Initial",IF(F10=2,"Partial",IF(F10=3,"Substantial","Comprehensive")))) -> Partial | K10: 3 | O10: 1
B11: EN04 | C11: Cloud infrastructure & API modernisation | D11: Data & Infrastructure | E11: XL | F11: 2 | G11: =IF(F11=0,"Not started",IF(F11=1,"Initial",IF(F11=2,"Partial",IF(F11=3,"Substantial","Comprehensive")))) -> Partial | J11: 3 | N11: 2
B12: EN05 | C12: AI skills & literacy programme | D12: Skills & Capability | E12: M | F12: 1 | G12: =IF(F12=0,"Not started",IF(F12=1,"Initial",IF(F12=2,"Partial",IF(F12=3,"Substantial","Comprehensive")))) -> Initial | L12: 1 | M12: 3 | O12: 1
B13: EN06 | C13: Unstructured data & document intelligence | D13: Data & Infrastructure | E13: L | F13: 0 | G13: =IF(F13=0,"Not started",IF(F13=1,"Initial",IF(F13=2,"Partial",IF(F13=3,"Substantial","Comprehensive")))) -> Not started | I13: 2 | J13: 1 | N13: 1
B14: EN07 | C14: Customer data & consent management | D14: Data & Infrastructure | E14: L | F14: 1 | G14: =IF(F14=0,"Not started",IF(F14=1,"Initial",IF(F14=2,"Partial",IF(F14=3,"Substantial","Comprehensive")))) -> Initial | I14: 2 | K14: 1 | N14: 1
B15: EN08 | C15: Process standardisation & workflow automation | D15: Organisational & Process | E15: L | F15: 2 | G15: =IF(F15=0,"Not started",IF(F15=1,"Initial",IF(F15=2,"Partial",IF(F15=3,"Substantial","Comprehensive")))) -> Partial | L15: 3 | N15: 1

Sheet Use Cases
B2: USE CASES
B3: One row per use case. Dropdown columns (Domain, Theme, State, Risk) reference the lookup tables in Config. Multi-value fields use pipe | delimiter. Notes column is internal only — not exported.
B6: Use Case ID | C6: Name | D6: Business Domain | E6: Investment Theme | F6: Current State | G6: Regulatory Risk | H6: Notes (not exported) | I6: Enables (pipe-separated) | J6: Implementation Enablers (pipe-separated)
B7: UC01 | C7: Automated FNOL triage | D7: Claims | E7: Efficiency | F7: Identified | G7: Medium | I7: UC02|UC03 | J7: EN01|EN04|EN08
B8: UC02 | C8: AI-assisted claims liability assessment | D8: Claims | E8: Intelligence | F8: Hypothetical | G8: High | J8: EN01|EN02|EN03|EN06
B9: UC03 | C9: Claims fraud detection — motor | D9: Claims | E9: Intelligence | F9: Piloted | G9: High | I9: UC04 | J9: EN01|EN02|EN03
B10: UC04 | C10: Claims fraud detection — home & contents | D10: Claims | E10: Intelligence | F10: Hypothetical | G10: High | J10: EN01|EN02|EN03
B11: UC05 | C11: Claims document extraction & summarisation | D11: Claims | E11: Efficiency | F11: Identified | G11: Low | I11: UC02 | J11: EN06|EN08
B12: UC06 | C12: Predictive UW risk scoring — motor | D12: Personal Lines Underwriting | E12: Intelligence | F12: Hypothetical | G12: High | I12: UC07 | J12: EN01|EN02|EN03
B13: UC07 | C13: Predictive UW risk scoring — home | D13: Personal Lines Underwriting | E13: Intelligence | F13: Hypothetical | G13: High | J13: EN01|EN02|EN03
B14: UC08 | C14: Underwriting referral assist | D14: Personal Lines Underwriting | E14: Efficiency | F14: Identified | G14: Medium | J14: EN06|EN05
B15: UC09 | C15: Automated policy endorsement processing | D15: Operations & IT | E15: Efficiency | F15: Identified | G15: Low | J15: EN04|EN08
B16: UC10 | C16: AI-powered customer self-service | D16: Customer & Distribution | E16: Engagement | F16: Identified | G16: Medium | J16: EN04|EN07|EN05
B17: UC11 | C17: Personalised renewal pricing & retention | D17: Customer & Distribution | E17: Intelligence | F17: Hypothetical | G17: High | J17: EN01|EN02|EN03|EN07
B18: UC12 | C18: Next best action for inbound contacts | D18: Customer & Distribution | E18: Engagement | F18: Hypothetical | G18: Medium | J18: EN01|EN07|EN04
B19: UC13 | C19: Complaint root cause analysis | D19: Compliance & Risk | E19: Intelligence | F19: Identified | G19: Medium | J19: EN06|EN02
B20: UC14 | C20: Regulatory change impact assessment | D20: Compliance & Risk | E20: Efficiency | F20: Identified | G20: Low | J20: EN06|EN03
B21: UC15 | C21: Automated conduct risk monitoring | D21: Compliance & Risk | E21: Intelligence | F21: Hypothetical | G21: High | J21: EN01|EN03|EN06
B22: UC16 | C22: AI-assisted actuarial reserving | D22: Finance & Actuarial | E22: Intelligence | F22: Hypothetical | G22: High | J22: EN01|EN02|EN03
B23: UC17 | C23: Finance process automation — reconciliations | D23: Finance & Actuarial | E23: Efficiency | F23: Identified | G23: Low | J23: EN04|EN08
B24: UC18 | C24: Broker relationship scoring & segmentation | D24: Customer & Distribution | E24: Intelligence | F24: Identified | G24: Low | J24: EN01|EN02
... B28: UC22 | C28: HR & workforce planning intelligence | D28: Operations & IT | E28: Intelligence | F28: Identified | G28: Low | J28: EN01|EN02
B29: UC23 | C29: AI co-pilot for contact centre agents | D29: Customer & Distribution | E29: Efficiency | F29: Identified | G29: Medium | I29: UC12 | J29: EN05|EN06|EN04
B30: UC24 | C30: CAT event claims surge management | D30: Claims | E30: Engagement | F30: Hypothetical | G30: High | J30: EN01|EN04|EN08
B31: UC25 | C31: Pricing optimisation — competitive positioning | D31: Personal Lines Underwriting | E31: Intelligence | F31: Hypothetical | G31: High | J31: EN01|EN02|EN03
B32: UC26 | C32: Internal knowledge management assistant | D32: Operations & IT | E32: Efficiency | F32: Identified | G32: Low | I32: UC08|UC23 | J32: EN06|EN05
B33: UC27 | C33: Vulnerable customer identification & routing | D33: Customer & Distribution | E33: Engagement | F33: Identified | G33: High | J33: EN07|EN03|EN05
B34: UC28 | C34: Supplier & third-party risk monitoring | D34: Compliance & Risk | E34: Intelligence | F34: Hypothetical | G34: Medium | J34: EN06|EN02
B35: UC29 | C35: Automated MI & management reporting | D35: Finance & Actuarial | E35: Efficiency | F35: Identified | G35: Low | J35: EN01|EN04
B36: UC30 | C36: Proactive churn prevention — personal lines | D36: Customer & Distribution | E36: Engagement | F36: Hypothetical | G36: Medium | J36: EN01|EN07|EN02
B37: UC31 | C37: Automatic HR onboarding | D37: Operations & IT | E37: Efficiency | F37: Identified | G37: Low | J37: EN05

Sheet Impact Scores
B2: IMPACT SCORES
B3: One row per use case. UC ID and Name auto-populate from the Use Cases tab. Enter scores 1–5 in each factor column. The Weighted Score column recalculates automatically. Column headers in row 6 are Factor IDs (machine-readable); row 7 shows friendly names. Yellow cells contain formulas — do not edit manually.
B4: FIXED COLUMNS | E4: SCORES BY FACTOR (1 = low … 5 = high)
E5: {=IFERROR(INDEX(ImpactFactors, COLUMN()-4, 1), "")} -> IF01 | F5: {=IFERROR(INDEX(ImpactFactors, COLUMN()-4, 1), "")} -> IF02 | G5: {=IFERROR(INDEX(ImpactFactors, COLUMN()-4, 1), "")} -> IF03 | H5: {=IFERROR(INDEX(ImpactFactors, COLUMN()-4, 1), "")} -> IF04 | I5: {=IFERROR(INDEX(ImpactFactors, COLUMN()-4, 1), "")} -> IF05 | J5: {=IFERROR(INDEX(ImpactFactors, COLUMN()-4, 1), "")} -> IF06 | K5: {=IFERROR(INDEX(ImpactFactors, COLUMN()-4, 1), "")} -> IF07 | L5: {=IFERROR(INDEX(ImpactFactors, COLUMN()-4, 1), "")} | ... N5: {=IFERROR(INDEX(ImpactFactors, COLUMN()-4, 1), "")}
B6: Use Case ID | C6: Use Case Name | D6: Weighted Score (calculated) | E6: =IFERROR(VLOOKUP(E5,ImpactFactors,2,FALSE()),E5) -> Revenue growth | F6: =IFERROR(VLOOKUP(F5,ImpactFactors,2,FALSE()),F5) -> Cost reduction / efficiency | G6: =IFERROR(VLOOKUP(G5,ImpactFactors,2,FALSE()),G5) -> Risk reduction | H6: =IFERROR(VLOOKUP(H5,ImpactFactors,2,FALSE()),H5) -> Customer experience | I6: =IFERROR(VLOOKUP(I5,ImpactFactors,2,FALSE()),I5) -> Strategic differentiation | J6: =IFERROR(VLOOKUP(J5,ImpactFactors,2,FALSE()),J5) -> Employee experience | K6: =IFERROR(VLOOKUP(K5,ImpactFactors,2,FALSE()),K5) -> Learning | L6: =IFERROR(VLOOKUP(L5,ImpactFactors,2,FALSE()),L5) | ... N6: =IFERROR(VLOOKUP(N5,ImpactFactors,2,FALSE()),N5)
D7: WEIGHTS → | E7: =IF(E5="","",IFERROR(VLOOKUP(E5,ImpactFactors,3,FALSE()),0)) -> 20 | F7: =IF(F5="","",IFERROR(VLOOKUP(F5,ImpactFactors,3,FALSE()),0)) -> 20 | G7: =IF(G5="","",IFERROR(VLOOKUP(G5,ImpactFactors,3,FALSE()),0)) -> 20 | H7: =IF(H5="","",IFERROR(VLOOKUP(H5,ImpactFactors,3,FALSE()),0)) -> 15 | I7: =IF(I5="","",IFERROR(VLOOKUP(I5,ImpactFactors,3,FALSE()),0)) -> 15 | J7: =IF(J5="","",IFERROR(VLOOKUP(J5,ImpactFactors,3,FALSE()),0)) -> 10 | K7: =IF(K5="","",IFERROR(VLOOKUP(K5,ImpactFactors,3,FALSE()),0)) -> 20 | L7: =IF(L5="","",IFERROR(VLOOKUP(L5,ImpactFactors,3,FALSE()),0)) | ... N7: =IF(N5="","",IFERROR(VLOOKUP(N5,ImpactFactors,3,FALSE()),0))
B8: =IF('Use Cases'!B7<>"",'Use Cases'!B7,"") -> UC01 | C8: =IFERROR(VLOOKUP(B8,'Use Cases'!$B$7:$C$506,2,FALSE()),"") -> Automated FNOL triage | D8: =IF(B8<>"",IFERROR(SUMPRODUCT(E8:N8,E$7:N$7)/SUM(E$7:N$7),""),"") -> 3.0416667 | E8: 2 | F8: 5 | G8: 3 | H8: 4 | I8: 3 | J8: 4 | K8: 1
B9: =IF('Use Cases'!B8<>"",'Use Cases'!B8,"") -> UC02 | C9: =IFERROR(VLOOKUP(B9,'Use Cases'!$B$7:$C$506,2,FALSE()),"") -> AI-assisted claims liability assessment | D9: =IF(B9<>"",IFERROR(SUMPRODUCT(E9:N9,E$7:N$7)/SUM(E$7:N$7),""),"") -> 3.4583333 | E9: 2 | F9: 4 | G9: 5 | H9: 3 | I9: 4 | J9: 3 | K9: 3
B10: =IF('Use Cases'!B9<>"",'Use Cases'!B9,"") -> UC03 | C10: =IFERROR(VLOOKUP(B10,'Use Cases'!$B$7:$C$506,2,FALSE()),"") -> Claims fraud detection — motor | D10: =IF(B10<>"",IFERROR(SUMPRODUCT(E10:N10,E$7:N$7)/SUM(E$7:N$7),""),"") -> 3.0416667 | E10: 2 | F10: 4 | G10: 5 | H10: 2 | I10: 3 | J10: 3 | K10: 2
B11: =IF('Use Cases'!B10<>"",'Use Cases'!B10,"") -> UC04 | C11: =IFERROR(VLOOKUP(B11,'Use Cases'!$B$7:$C$506,2,FALSE()),"") -> Claims fraud detection — home & contents | D11: =IF(B11<>"",IFERROR(SUMPRODUCT(E11:N11,E$7:N$7)/SUM(E$7:N$7),""),"") -> 2.9166667 | E11: 2 | F11: 4 | G11: 5 | H11: 2 | I11: 2 | J11: 3 | K11: 2
B12: =IF('Use Cases'!B11<>"",'Use Cases'!B11,"") -> UC05 | C12: =IFERROR(VLOOKUP(B12,'Use Cases'!$B$7:$C$506,2,FALSE()),"") -> Claims document extraction & summarisation | D12: =IF(B12<>"",IFERROR(SUMPRODUCT(E12:N12,E$7:N$7)/SUM(E$7:N$7),""),"") -> 3.0416667 | E12: 1 | F12: 5 | G12: 2 | H12: 3 | I12: 2 | J12: 5 | K12: 4
B13: =IF('Use Cases'!B12<>"",'Use Cases'!B12,"") -> UC06 | C13: =IFERROR(VLOOKUP(B13,'Use Cases'!$B$7:$C$506,2,FALSE()),"") -> Predictive UW risk scoring — motor | D13: =IF(B13<>"",IFERROR(SUMPRODUCT(E13:N13,E$7:N$7)/SUM(E$7:N$7),""),"") -> 3.2083333 | E13: 4 | F13: 3 | G13: 5 | H13: 2 | I13: 5 | J13: 2 | K13: 1
B14: =IF('Use Cases'!B13<>"",'Use Cases'!B13,"") -> UC07 | C14: =IFERROR(VLOOKUP(B14,'Use Cases'!$B$7:$C$506,2,FALSE()),"") -> Predictive UW risk scoring — home | D14: =IF(B14<>"",IFERROR(SUMPRODUCT(E14:N14,E$7:N$7)/SUM(E$7:N$7),""),"") -> 3.25 | E14: 4 | F14: 3 | G14: 5 | H14: 2 | I14: 4 | J14: 2 | K14: 2
B15: =IF('Use Cases'!B14<>"",'Use Cases'!B14,"") -> UC08 | C15: =IFERROR(VLOOKUP(B15,'Use Cases'!$B$7:$C$506,2,FALSE()),"") -> Underwriting referral assist | D15: =IF(B15<>"",IFERROR(SUMPRODUCT(E15:N15,E$7:N$7)/SUM(E$7:N$7),""),"") -> 3.125 | E15: 2 | F15: 4 | G15: 3 | H15: 2 | I15: 3 | J15: 4 | K15: 4
B16: =IF('Use Cases'!B15<>"",'Use Cases'!B15,"") -> UC09 | C16: =IFERROR(VLOOKUP(B16,'Use Cases'!$B$7:$C$506,2,FALSE()),"") -> Automated policy endorsement processing | D16: =IF(B16<>"",IFERROR(SUMPRODUCT(E16:N16,E$7:N$7)/SUM(E$7:N$7),""),"") -> 2.625 | E16: 1 | F16: 5 | G16: 2 | H16: 3 | I16: 2 | J16: 4 | K16: 2
B17: =IF('Use Cases'!B16<>"",'Use Cases'!B16,"") -> UC10 | C17: =IFERROR(VLOOKUP(B17,'Use Cases'!$B$7:$C$506,2,FALSE()),"") -> AI-powered customer self-service | D17: =IF(B17<>"",IFERROR(SUMPRODUCT(E17:N17,E$7:N$7)/SUM(E$7:N$7),""),"") -> 3.5416667 | E17: 3 | F17: 4 | G17: 2 | H17: 5 | I17: 4 | J17: 3 | K17: 4
B18: =IF('Use Cases'!B17<>"",'Use Cases'!B17,"") -> UC11 | C18: =IFERROR(VLOOKUP(B18,'Use Cases'!$B$7:$C$506,2,FALSE()),"") -> Personalised renewal pricing & retention | D18: =IF(B18<>"",IFERROR(SUMPRODUCT(E18:N18,E$7:N$7)/SUM(E$7:N$7),""),"") -> 3.625 | E18: 5 | F18: 3 | G18: 3 | H18: 4 | I18: 5 | J18: 2 | K18: 3
B19: =IF('Use Cases'!B18<>"",'Use Cases'!B18,"") -> UC12 | C19: =IFERROR(VLOOKUP(B19,'Use Cases'!$B$7:$C$506,2,FALSE()),"") -> Next best action for inbound contacts | D19: =IF(B19<>"",IFERROR(SUMPRODUCT(E19:N19,E$7:N$7)/SUM(E$7:N$7),""),"") -> 3.4166667 | E19: 4 | F19: 2 | G19: 2 | H19: 4 | I19: 4 | J19: 3 | K19: 5
... B38: =IF('Use Cases'!B37<>"",'Use Cases'!B37,"") -> UC31 | C38: =IFERROR(VLOOKUP(B38,'Use Cases'!$B$7:$C$506,2,FALSE()),"") -> Automatic HR onboarding | D38: =IF(B38<>"",IFERROR(SUMPRODUCT(E38:N38,E$7:N$7)/SUM(E$7:N$7),""),"") -> 2.0833333 | E38: 1 | F38: 4 | G38: 3 | H38: 1 | I38: 1 | J38: 4 | K38: 1
B39: =IF('Use Cases'!B38<>"",'Use Cases'!B38,"") | C39: =IFERROR(VLOOKUP(B39,'Use Cases'!$B$7:$C$506,2,FALSE()),"") | D39: =IF(B39<>"",IFERROR(SUMPRODUCT(E39:N39,E$7:N$7)/SUM(E$7:N$7),""),"")
B40: =IF('Use Cases'!B39<>"",'Use Cases'!B39,"") | C40: =IFERROR(VLOOKUP(B40,'Use Cases'!$B$7:$C$506,2,FALSE()),"") | D40: =IF(B40<>"",IFERROR(SUMPRODUCT(E40:N40,E$7:N$7)/SUM(E$7:N$7),""),"")
B41: =IF('Use Cases'!B40<>"",'Use Cases'!B40,"") | C41: =IFERROR(VLOOKUP(B41,'Use Cases'!$B$7:$C$506,2,FALSE()),"") | D41: =IF(B41<>"",IFERROR(SUMPRODUCT(E41:N41,E$7:N$7)/SUM(E$7:N$7),""),"")
B42: =IF('Use Cases'!B41<>"",'Use Cases'!B41,"") | C42: =IFERROR(VLOOKUP(B42,'Use Cases'!$B$7:$C$506,2,FALSE()),"") | D42: =IF(B42<>"",IFERROR(SUMPRODUCT(E42:N42,E$7:N$7)/SUM(E$7:N$7),""),"")
B43: =IF('Use Cases'!B42<>"",'Use Cases'!B42,"") | C43: =IFERROR(VLOOKUP(B43,'Use Cases'!$B$7:$C$506,2,FALSE()),"") | D43: =IF(B43<>"",IFERROR(SUMPRODUCT(E43:N43,E$7:N$7)/SUM(E$7:N$7),""),"")
B44: =IF('Use Cases'!B43<>"",'Use Cases'!B43,"") | C44: =IFERROR(VLOOKUP(B44,'Use Cases'!$B$7:$C$506,2,FALSE()),"") | D44: =IF(B44<>"",IFERROR(SUMPRODUCT(E44:N44,E$7:N$7)/SUM(E$7:N$7),""),"")
B45: =IF('Use Cases'!B44<>"",'Use Cases'!B44,"") | C45: =IFERROR(VLOOKUP(B45,'Use Cases'!$B$7:$C$506,2,FALSE()),"") | D45: =IF(B45<>"",IFERROR(SUMPRODUCT(E45:N45,E$7:N$7)/SUM(E$7:N$7),""),"")
B46: =IF('Use Cases'!B45<>"",'Use Cases'!B45,"") | C46: =IFERROR(VLOOKUP(B46,'Use Cases'!$B$7:$C$506,2,FALSE()),"") | D46: =IF(B46<>"",IFERROR(SUMPRODUCT(E46:N46,E$7:N$7)/SUM(E$7:N$7),""),"")
B47: =IF('Use Cases'!B46<>"",'Use Cases'!B46,"") | C47: =IFERROR(VLOOKUP(B47,'Use Cases'!$B$7:$C$506,2,FALSE()),"") | D47: =IF(B47<>"",IFERROR(SUMPRODUCT(E47:N47,E$7:N$7)/SUM(E$7:N$7),""),"")
B48: =IF('Use Cases'!B47<>"",'Use Cases'!B47,"") | C48: =IFERROR(VLOOKUP(B48,'Use Cases'!$B$7:$C$506,2,FALSE()),"") | D48: =IF(B48<>"",IFERROR(SUMPRODUCT(E48:N48,E$7:N$7)/SUM(E$7:N$7),""),"")
B49: =IF('Use Cases'!B48<>"",'Use Cases'!B48,"") | C49: =IFERROR(VLOOKUP(B49,'Use Cases'!$B$7:$C$506,2,FALSE()),"") | D49: =IF(B49<>"",IFERROR(SUMPRODUCT(E49:N49,E$7:N$7)/SUM(E$7:N$7),""),"")
B50: =IF('Use Cases'!B49<>"",'Use Cases'!B49,"") | C50: =IFERROR(VLOOKUP(B50,'Use Cases'!$B$7:$C$506,2,FALSE()),"") | D50: =IF(B50<>"",IFERROR(SUMPRODUCT(E50:N50,E$7:N$7)/SUM(E$7:N$7),""),"")
... B106: =IF('Use Cases'!B105<>"",'Use Cases'!B105,"") | C106: =IFERROR(VLOOKUP(B106,'Use Cases'!$B$7:$C$506,2,FALSE()),"") | D106: =IF(B106<>"",IFERROR(SUMPRODUCT(E106:N106,E$7:N$7)/SUM(E$7:N$7),""),"")

Sheet Readiness Scores
B2: READINESS SCORES
B3: One row per use case. UC ID and Name auto-populate from the Use Cases tab. Enter scores 1–5 in each factor column. The Weighted Score column recalculates automatically. Column headers in row 6 are Factor IDs (machine-readable); row 7 shows friendly names. Yellow cells contain formulas — do not edit manually.
B4: FIXED COLUMNS | E4: SCORES BY FACTOR (1 = low … 5 = high)
E5: {=IFERROR(INDEX(ReadinessFactors, COLUMN()-4, 1), "")} -> RF01 | F5: {=IFERROR(INDEX(ReadinessFactors, COLUMN()-4, 1), "")} -> RF02 | G5: {=IFERROR(INDEX(ReadinessFactors, COLUMN()-4, 1), "")} -> RF03 | H5: {=IFERROR(INDEX(ReadinessFactors, COLUMN()-4, 1), "")} -> RF04 | I5: {=IFERROR(INDEX(ReadinessFactors, COLUMN()-4, 1), "")} -> RF05 | J5: {=IFERROR(INDEX(ReadinessFactors, COLUMN()-4, 1), "")} -> RF06 | K5: {=IFERROR(INDEX(ReadinessFactors, COLUMN()-4, 1), "")} -> RF07 | L5: {=IFERROR(INDEX(ReadinessFactors, COLUMN()-4, 1), "")} | ... N5: {=IFERROR(INDEX(ReadinessFactors, COLUMN()-4, 1), "")}
B6: Use Case ID | C6: Use Case Name | D6: Weighted Score (calculated) | E6: =IFERROR(VLOOKUP(E5,ReadinessFactors,2,FALSE()),E5) -> Data availability & quality | F6: =IFERROR(VLOOKUP(F5,ReadinessFactors,2,FALSE()),F5) -> Technical infrastructure | G6: =IFERROR(VLOOKUP(G5,ReadinessFactors,2,FALSE()),G5) -> Governance & compliance readiness | H6: =IFERROR(VLOOKUP(H5,ReadinessFactors,2,FALSE()),H5) -> Organisational & process readiness | I6: =IFERROR(VLOOKUP(I5,ReadinessFactors,2,FALSE()),I5) -> Skills & capability | J6: =IFERROR(VLOOKUP(J5,ReadinessFactors,2,FALSE()),J5) -> Implementation effort | K6: =IFERROR(VLOOKUP(K5,ReadinessFactors,2,FALSE()),K5) -> Executive & stakeholder support | L6: =IFERROR(VLOOKUP(L5,ReadinessFactors,2,FALSE()),L5) | ... N6: =IFERROR(VLOOKUP(N5,ReadinessFactors,2,FALSE()),N5)
D7: WEIGHTS → | E7: =IF(E5="","",IFERROR(VLOOKUP(E5,ReadinessFactors,3,FALSE()),0)) -> 20 | F7: =IF(F5="","",IFERROR(VLOOKUP(F5,ReadinessFactors,3,FALSE()),0)) -> 15 | G7: =IF(G5="","",IFERROR(VLOOKUP(G5,ReadinessFactors,3,FALSE()),0)) -> 20 | H7: =IF(H5="","",IFERROR(VLOOKUP(H5,ReadinessFactors,3,FALSE()),0)) -> 15 | I7: =IF(I5="","",IFERROR(VLOOKUP(I5,ReadinessFactors,3,FALSE()),0)) -> 10 | J7: =IF(J5="","",IFERROR(VLOOKUP(J5,ReadinessFactors,3,FALSE()),0)) -> 10 | K7: =IF(K5="","",IFERROR(VLOOKUP(K5,ReadinessFactors,3,FALSE()),0)) -> 10 | L7: =IF(L5="","",IFERROR(VLOOKUP(L5,ReadinessFactors,3,FALSE()),0)) | ... N7: =IF(N5="","",IFERROR(VLOOKUP(N5,ReadinessFactors,3,FALSE()),0))
B8: =IF('Use Cases'!B7<>"",'Use Cases'!B7,"") -> UC01 | C8: =IFERROR(VLOOKUP(B8,'Use Cases'!$B$7:$C$506,2,FALSE()),"") -> Automated FNOL triage | D8: =IF(B8<>"",IFERROR(SUMPRODUCT(E8:N8,E$7:N$7)/SUM(E$7:N$7),""),"") -> 2.6 | E8: 3 | F8: 2 | G8: 3 | H8: 2 | I8: 2 | J8: 3 | K8: 3
B9: =IF('Use Cases'!B8<>"",'Use Cases'!B8,"") -> UC02 | C9: =IFERROR(VLOOKUP(B9,'Use Cases'!$B$7:$C$506,2,FALSE()),"") -> AI-assisted claims liability assessment | D9: =IF(B9<>"",IFERROR(SUMPRODUCT(E9:N9,E$7:N$7)/SUM(E$7:N$7),""),"") -> 1.9 | E9: 2 | F9: 2 | G9: 1 | H9: 2 | I9: 2 | J9: 2 | K9: 3
B10: =IF('Use Cases'!B9<>"",'Use Cases'!B9,"") -> UC03 | C10: =IFERROR(VLOOKUP(B10,'Use Cases'!$B$7:$C$506,2,FALSE()),"") -> Claims fraud detection — motor | D10: =IF(B10<>"",IFERROR(SUMPRODUCT(E10:N10,E$7:N$7)/SUM(E$7:N$7),""),"") -> 2.9 | E10: 3 | F10: 3 | G10: 2 | H10: 3 | I10: 3 | J10: 3 | K10: 4
B11: =IF('Use Cases'!B10<>"",'Use Cases'!B10,"") -> UC04 | C11: =IFERROR(VLOOKUP(B11,'Use Cases'!$B$7:$C$506,2,FALSE()),"") -> Claims fraud detection — home & contents | D11: =IF(B11<>"",IFERROR(SUMPRODUCT(E11:N11,E$7:N$7)/SUM(E$7:N$7),""),"") -> 2.5 | E11: 2 | F11: 3 | G11: 2 | H11: 3 | I11: 2 | J11: 3 | K11: 3
B12: =IF('Use Cases'!B11<>"",'Use Cases'!B11,"") -> UC05 | C12: =IFERROR(VLOOKUP(B12,'Use Cases'!$B$7:$C$506,2,FALSE()),"") -> Claims document extraction & summarisation | D12: =IF(B12<>"",IFERROR(SUMPRODUCT(E12:N12,E$7:N$7)/SUM(E$7:N$7),""),"") -> 3.1 | E12: 3 | F12: 3 | G12: 3 | H12: 3 | I12: 3 | J12: 4 | K12: 3
B13: =IF('Use Cases'!B12<>"",'Use Cases'!B12,"") -> UC06 | C13: =IFERROR(VLOOKUP(B13,'Use Cases'!$B$7:$C$506,2,FALSE()),"") -> Predictive UW risk scoring — motor | D13: =IF(B13<>"",IFERROR(SUMPRODUCT(E13:N13,E$7:N$7)/SUM(E$7:N$7),""),"") -> 1.9 | E13: 2 | F13: 2 | G13: 1 | H13: 2 | I13: 2 | J13: 2 | K13: 3
B14: =IF('Use Cases'!B13<>"",'Use Cases'!B13,"") -> UC07 | C14: =IFERROR(VLOOKUP(B14,'Use Cases'!$B$7:$C$506,2,FALSE()),"") -> Predictive UW risk scoring — home | D14: =IF(B14<>"",IFERROR(SUMPRODUCT(E14:N14,E$7:N$7)/SUM(E$7:N$7),""),"") -> 1.9 | E14: 2 | F14: 2 | G14: 1 | H14: 2 | I14: 2 | J14: 2 | K14: 3
B15: =IF('Use Cases'!B14<>"",'Use Cases'!B14,"") -> UC08 | C15: =IFERROR(VLOOKUP(B15,'Use Cases'!$B$7:$C$506,2,FALSE()),"") -> Underwriting referral assist | D15: =IF(B15<>"",IFERROR(SUMPRODUCT(E15:N15,E$7:N$7)/SUM(E$7:N$7),""),"") -> 2.9 | E15: 3 | F15: 3 | G15: 3 | H15: 3 | I15: 2 | J15: 3 | K15: 3
B16: =IF('Use Cases'!B15<>"",'Use Cases'!B15,"") -> UC09 | C16: =IFERROR(VLOOKUP(B16,'Use Cases'!$B$7:$C$506,2,FALSE()),"") -> Automated policy endorsement processing | D16: =IF(B16<>"",IFERROR(SUMPRODUCT(E16:N16,E$7:N$7)/SUM(E$7:N$7),""),"") -> 2.9 | E16: 4 | F16: 2 | G16: 3 | H16: 2 | I16: 3 | J16: 3 | K16: 3
B17: =IF('Use Cases'!B16<>"",'Use Cases'!B16,"") -> UC10 | C17: =IFERROR(VLOOKUP(B17,'Use Cases'!$B$7:$C$506,2,FALSE()),"") -> AI-powered customer self-service | D17: =IF(B17<>"",IFERROR(SUMPRODUCT(E17:N17,E$7:N$7)/SUM(E$7:N$7),""),"") -> 2.3 | E17: 3 | F17: 2 | G17: 2 | H17: 2 | I17: 2 | J17: 2 | K17: 3
B18: =IF('Use Cases'!B17<>"",'Use Cases'!B17,"") -> UC11 | C18: =IFERROR(VLOOKUP(B18,'Use Cases'!$B$7:$C$506,2,FALSE()),"") -> Personalised renewal pricing & retention | D18: =IF(B18<>"",IFERROR(SUMPRODUCT(E18:N18,E$7:N$7)/SUM(E$7:N$7),""),"") -> 1.9 | E18: 2 | F18: 2 | G18: 1 | H18: 2 | I18: 2 | J18: 2 | K18: 3
B19: =IF('Use Cases'!B18<>"",'Use Cases'!B18,"") -> UC12 | C19: =IFERROR(VLOOKUP(B19,'Use Cases'!$B$7:$C$506,2,FALSE()),"") -> Next best action for inbound contacts | D19: =IF(B19<>"",IFERROR(SUMPRODUCT(E19:N19,E$7:N$7)/SUM(E$7:N$7),""),"") -> 2.1 | E19: 2 | F19: 2 | G19: 2 | H19: 2 | I19: 2 | J19: 2 | K19: 3
... B38: =IF('Use Cases'!B37<>"",'Use Cases'!B37,"") -> UC31 | C38: =IFERROR(VLOOKUP(B38,'Use Cases'!$B$7:$C$506,2,FALSE()),"") -> Automatic HR onboarding | D38: =IF(B38<>"",IFERROR(SUMPRODUCT(E38:N38,E$7:N$7)/SUM(E$7:N$7),""),"") -> 2.3 | E38: 1 | F38: 4 | G38: 2 | H38: 2 | I38: 1 | J38: 3 | K38: 4
B39: =IF('Use Cases'!B38<>"",'Use Cases'!B38,"") | C39: =IFERROR(VLOOKUP(B39,'Use Cases'!$B$7:$C$506,2,FALSE()),"") | D39: =IF(B39<>"",IFERROR(SUMPRODUCT(E39:N39,E$7:N$7)/SUM(E$7:N$7),""),"")
B40: =IF('Use Cases'!B39<>"",'Use Cases'!B39,"") | C40: =IFERROR(VLOOKUP(B40,'Use Cases'!$B$7:$C$506,2,FALSE()),"") | D40: =IF(B40<>"",IFERROR(SUMPRODUCT(E40:N40,E$7:N$7)/SUM(E$7:N$7),""),"")
B41: =IF('Use Cases'!B40<>"",'Use Cases'!B40,"") | C41: =IFERROR(VLOOKUP(B41,'Use Cases'!$B$7:$C$506,2,FALSE()),"") | D41: =IF(B41<>"",IFERROR(SUMPRODUCT(E41:N41,E$7:N$7)/SUM(E$7:N$7),""),"")
B42: =IF('Use Cases'!B41<>"",'Use Cases'!B41,"") | C42: =IFERROR(VLOOKUP(B42,'Use Cases'!$B$7:$C$506,2,FALSE()),"") | D42: =IF(B42<>"",IFERROR(SUMPRODUCT(E42:N42,E$7:N$7)/SUM(E$7:N$7),""),"")
B43: =IF('Use Cases'!B42<>"",'Use Cases'!B42,"") | C43: =IFERROR(VLOOKUP(B43,'Use Cases'!$B$7:$C$506,2,FALSE()),"") | D43: =IF(B43<>"",IFERROR(SUMPRODUCT(E43:N43,E$7:N$7)/SUM(E$7:N$7),""),"")
B44: =IF('Use Cases'!B43<>"",'Use Cases'!B43,"") | C44: =IFERROR(VLOOKUP(B44,'Use Cases'!$B$7:$C$506,2,FALSE()),"") | D44: =IF(B44<>"",IFERROR(SUMPRODUCT(E44:N44,E$7:N$7)/SUM(E$7:N$7),""),"")
B45: =IF('Use Cases'!B44<>"",'Use Cases'!B44,"") | C45: =IFERROR(VLOOKUP(B45,'Use Cases'!$B$7:$C$506,2,FALSE()),"") | D45: =IF(B45<>"",IFERROR(SUMPRODUCT(E45:N45,E$7:N$7)/SUM(E$7:N$7),""),"")
B46: =IF('Use Cases'!B45<>"",'Use Cases'!B45,"") | C46: =IFERROR(VLOOKUP(B46,'Use Cases'!$B$7:$C$506,2,FALSE()),"") | D46: =IF(B46<>"",IFERROR(SUMPRODUCT(E46:N46,E$7:N$7)/SUM(E$7:N$7),""),"")
B47: =IF('Use Cases'!B46<>"",'Use Cases'!B46,"") | D47: =IF(B47<>"",IFERROR(SUMPRODUCT(E47:N47,E$7:N$7)/SUM(E$7:N$7),""),"")
B48: =IF('Use Cases'!B47<>"",'Use Cases'!B47,"") | D48: =IF(B48<>"",IFERROR(SUMPRODUCT(E48:N48,E$7:N$7)/SUM(E$7:N$7),""),"")
B49: =IF('Use Cases'!B48<>"",'Use Cases'!B48,"") | D49: =IF(B49<>"",IFERROR(SUMPRODUCT(E49:N49,E$7:N$7)/SUM(E$7:N$7),""),"")
B50: =IF('Use Cases'!B49<>"",'Use Cases'!B49,"") | D50: =IF(B50<>"",IFERROR(SUMPRODUCT(E50:N50,E$7:N$7)/SUM(E$7:N$7),""),"")
B51: =IF('Use Cases'!B50<>"",'Use Cases'!B50,"") | D51: =IF(B51<>"",IFERROR(SUMPRODUCT(E51:N51,E$7:N$7)/SUM(E$7:N$7),""),"")
B52: =IF('Use Cases'!B51<>"",'Use Cases'!B51,"") | D52: =IF(B52<>"",IFERROR(SUMPRODUCT(E52:N52,E$7:N$7)/SUM(E$7:N$7),""),"")
B53: =IF('Use Cases'!B52<>"",'Use Cases'!B52,"") | D53: =IF(B53<>"",IFERROR(SUMPRODUCT(E53:N53,E$7:N$7)/SUM(E$7:N$7),""),"")
B54: =IF('Use Cases'!B53<>"",'Use Cases'!B53,"") | D54: =IF(B54<>"",IFERROR(SUMPRODUCT(E54:N54,E$7:N$7)/SUM(E$7:N$7),""),"")
B55: =IF('Use Cases'!B54<>"",'Use Cases'!B54,"") | D55: =IF(B55<>"",IFERROR(SUMPRODUCT(E55:N55,E$7:N$7)/SUM(E$7:N$7),""),"")
B56: =IF('Use Cases'!B55<>"",'Use Cases'!B55,"") | D56: =IF(B56<>"",IFERROR(SUMPRODUCT(E56:N56,E$7:N$7)/SUM(E$7:N$7),""),"")
B57: =IF('Use Cases'!B56<>"",'Use Cases'!B56,"") | D57: =IF(B57<>"",IFERROR(SUMPRODUCT(E57:N57,E$7:N$7)/SUM(E$7:N$7),""),"")
B58: =IF('Use Cases'!B57<>"",'Use Cases'!B57,"") | D58: =IF(B58<>"",IFERROR(SUMPRODUCT(E58:N58,E$7:N$7)/SUM(E$7:N$7),""),"")
... B106: =IF('Use Cases'!B105<>"",'Use Cases'!B105,"") | D106: =IF(B106<>"",IFERROR(SUMPRODUCT(E106:N106,E$7:N$7)/SUM(E$7:N$7),""),"")
